<!DOCTYPE html>
<html lang="en">

<head>
    <meta charset="UTF-8">
    <meta http-equiv="X-UA-Compatible" content="IE=edge">
    <meta name="viewport" content="width=device-width, initial-scale=1.0">
    <title>Document</title>
</head>

<body>
    <script>
        /*
                // 1.Promise 对象抛出的错误不会传递到外层代码
                const someAsyncThing = function () {
                    return new Promise(function (resolve, reject) {
                        // 这一行会报错，因为x没有声明
                        resolve(x + 2);
                    });
                };
                someAsyncThing().then(function() {
                    console.log('everything is great');
                });
        
                setTimeout(() => {
                    console.log('这里打印不会被影响');
                }, 2000);
        
                // Promise 内部的错误不会影响到 Promise 外部的代码，通俗的说法就是“Promise 会吃掉错误”。
         */

        /*
        // 2.建议：Promise对象 后面跟一个catch()方法，用来捕捉Promise内部发生的错误，catch()返回的还是一个Promise对象，因此后面还可以执行then()方法
        const someAsyncThing = function () {
            return new Promise(function (resolve, reject) {
                // 这一行会报错，因为x没有声明
                resolve(x + 2);
            });
        };
        someAsyncThing().catch(function(error) {
            console.log('oh no', error);
            // console.log(error);
        }).then((res) => {
            console.log(res);
            console.log('carry on');
        })
 */

        //  3.catch()方法之中，还能再抛出错误。
        // const someAsyncThing = function () {
        //     return new Promise(function (resolve, reject) {
        //         // 这一行会报错，因为x没有声明
        //         resolve(x + 2);
        //     });
        // };
        // someAsyncThing().then(() => {
        //     return someAsyncThing();
        // }).catch((error) => {
        //     console.log('oh no' + error);
        //     // 下面这一行会报错，因为y没有被定义
        //     y + 2;
        // }).then(() => {
        //     console.log('carry on');
        // })

        // 3.1 改造上面代码，捕捉到 y + 2 这个错误
        const someAsyncThing = function () {
            return new Promise(function (resolve, reject) {
                // 这一行会报错，因为x没有声明
                resolve(x + 2);
            });
        };
        someAsyncThing().then(() => {
            return someAsyncThing();
        }).catch((error) => {
            console.log('oh no' + error);
            // 下面这一行会报错，因为y没有被定义
            y + 2;
        }).catch((error) => {
            console.log('oh no 又错了' + error);
        })

    </script>
</body>

</html>